Workbook

Sheet Okuyun
A1: Dincel Çelik – Ürün ve Barkod Listesi (Düzeltme Talebi)
A2: Bu dosya, gönderdiğiniz iki listenin birleşimidir: "Ürün Listesi" sayfasındaki ilk liste + sonradan gönderdiğiniz "barkod_listesi.xlsx".
A3: İsteğiniz üzerine barkod_listesi.xlsx'teki COŞ_D, EFG ve Lüx maşa 805 / 806 / 807 satırları çıkarıldı. Kontrol tarihi: 04.10.2026.
A5: Ne yapmanız gerekiyor?
A6: "Ürün Listesi" sayfasında sağdaki yeni sütunlara bakın. "Durum" sütunu DÜZELTME GEREKLİ olan satırlarda "Not" sütunu sorunu ve ne yapılacağını anlatır.
A7: Lütfen yalnızca koyu başlıklı SARI sütunları doldurun:
A8: • Doğru Barkod: Ürünün kutusunda/etiketinde yazan, o ürüne ait 13 haneli barkod.
A9: • Doğru Ürün Kodu: Kod boş ya da yanlışsa doğru DNC kodu (örnek: DNC-175). Doğruysa boş bırakın.
A10: • Üretici Açıklaması: Kısa açıklama (örnek: "715 Pasta Maşası'na ait", "üretimden kalktı", "listeden çıkarılsın").
A11: "Durum" sütununa filtre uygulayıp yalnızca DÜZELTME GEREKLİ satırlarını görebilirsiniz. TAMAM satırlarında işlem gerekmez.
A12: Diğer sütunlara ve sayfalara (Özet, Kontrol Edilecekler, Fotoğraflar) dokunmanız gerekmiyor.
A14: Örnek doldurulmuş satır
A15: Ürün Kodu | B15: Barkod Değeri | C15: Durum | D15: Not (ne yapılmalı) | E15: Doğru Barkod | F15: Doğru Ürün Kodu | G15: Üretici Açıklaması
A16: DNC-175 | B16: 8683613550715 | C16: DÜZELTME GEREKLİ | D16: 8683613550715 barkodu şu ürün(ler)de de kullanılmış: DNC-038 (Damla Pasta Maşası)… | E16: 8683613550XXX | G16: 715 barkodu DNC-038 Pasta Maşası'na ait; Mira Gold kepçeye yeni barkod verildi.
A17: ("XXX" yalnızca örnektir; gerçek barkodu yazın.)
A19: Durum özeti
A20: TAMAM | B20: =COUNTIF('Ürün Listesi'!$Q$2:$Q$217,"TAMAM")
A21: DÜZELTME GEREKLİ | B21: =COUNTIF('Ürün Listesi'!$Q$2:$Q$217,"DÜZELTME GEREKLİ")
A22: Toplam satır | B22: =COUNTA('Ürün Listesi'!$A$2:$A$217)
A23: Doldurulan "Doğru Barkod" | B23: =COUNTA('Ürün Listesi'!$S$2:$S$217)

Sheet Ürün Listesi
A1: Ürün Kodu | B1: Standart Ürün Adı | C1: Ana Kategori | D1: Alt Kategori | E1: Model / Seri | F1: Kaplama | G1: Paket | H1: Paketteki Adet | I1: Çelik | J1: Barkod Dosyası (.btw) | K1: Kodla Eşleşen Foto | L1: Klasör | M1: Orijinal Dosya Adı | N1: Kontrol Notu | O1: Barkod Değeri | P1: Barkod – barkod_listesi.xlsx | Q1: Durum | R1: Not (ne yapılmalı) | S1: Doğru Barkod | T1: Doğru Ürün Kodu | U1: Üretici Açıklaması
A2: DNC-097 | B2: Platin Dondurma Kaşığı (6'lı) | C2: Kaşık | D2: Dondurma Kaşığı | E2: Platin | F2: Sade | G2: 6'lı | H2: 6 | J2: DNC-097 6'LI PLATİN DONDURMA KAŞIK.btw | K2: DNC-097 6'LI PLATİN DONDURMA KAŞIK.jpeg | L2: PLATİN | M2: DNC-097 6'LI PLATİN DONDURMA KAŞIK | O2: 8683613550081 | P2: 8683613550081 | Q2: TAMAM
A3: DNC-008 | B3: Platin Dondurma Kaşığı (12'li) | C3: Kaşık | D3: Dondurma Kaşığı | E3: Platin | F3: Sade | G3: 12'li (1 DZ) | H3: 12 | J3: DNC-008 1 DZ PLATİN DONDURMA KAŞIK.btw | L3: PLATİN | M3: DNC-008 1 DZ PLATİN DONDURMA KAŞIK | O3: 8683581657089 | P3: 8683581657089 | Q3: TAMAM
A4: DNC-155 | B4: Platin Dondurma Kaşığı Titanium (6'lı) | C4: Kaşık | D4: Dondurma Kaşığı | E4: Platin | F4: Titanium | G4: 6'lı | H4: 6 | J4: DNC-155 6,LI TİTANİUM DONDURMA KAŞIK.btw | K4: DNC_155 6,LIGOLD DONDURMAKAŞIK.jpeg, DNC_155 6,LIGOLDDONDURMAKAŞIKKUTULU.jpeg | L4: PLATİN | M4: DNC-155 6,LI TİTANİUM DONDURMA KAŞIK | N4: Barkod adı 'TİTANİUM', fotoğraf adları 'GOLD' diyor — kaplamayı teyit et. | O4: 8683613550784 | P4: 8683613550784 | Q4: DÜZELTME GEREKLİ | R4: 8683613550784 barkodu şu ürün(ler)de de kullanılmış: DNC-143 (DNC_143 OKYANUS SOS SERVİS KAŞIK); DNC-182 (DNC_182 LİLİUM GÜMÜŞ AMBER SOS SERVİS SET); DNC-042 (DNC-042 MAŞA SET GOLD BEYAZ). Bir barkod yalnızca tek bir ürüne ait olmalı. Bu ürünün kutusundaki/etiketindeki gerçek barkodu yazın; bu barkod başka ürüne aitse bu ürüne yeni barkod verin.
A5: DNC-096 | B5: Platin Nescafe Kaşığı (6'lı) | C5: Kaşık | D5: Nescafe Kaşığı | E5: Platin | F5: Sade | G5: 6'lı | H5: 6 | J5: DNC-096 6,LI PLATİN NESCAFE KAŞIK.btw | K5: DNC_096 6,LI NESTCAFE KAŞIK.jpeg | L5: PLATİN | M5: DNC-096 6,LI PLATİN NESCAFE KAŞIK | O5: 8683613550074 | P5: 8683613550074 | Q5: TAMAM
A6: DNC-009 | B6: Platin Nescafe Kaşığı (12'li) | C6: Kaşık | D6: Nescafe Kaşığı | E6: Platin | F6: Sade | G6: 12'li (1 DZ) | H6: 12 | J6: DNC-009 1 DZ PLATİN NESCAFE KAŞIK.btw | L6: PLATİN | M6: DNC-009 1 DZ PLATİN NESCAFE KAŞIK | O6: 8683581657072 | P6: 8683581657072 | Q6: TAMAM
A7: DNC-029 | B7: Platin Nescafe Kaşığı Titanium (6'lı) | C7: Kaşık | D7: Nescafe Kaşığı | E7: Platin | F7: Titanium | G7: 6'lı | H7: 6 | J7: DNC-029 PLATİN 6,LI NESTCAFE KAŞIK TİTANİUM.btw | L7: PLATİN | M7: DNC-029 PLATİN 6,LI NESTCAFE KAŞIK TİTANİUM | O7: 8683581657560 | P7: 8683581657560 | Q7: TAMAM
A8: DNC-092 | B8: Platin Tatlı Kaşığı (6'lı) | C8: Kaşık | D8: Tatlı Kaşığı | E8: Platin | F8: Sade | G8: 6'lı | H8: 6 | J8: DNC-092 PLATİN 6'LI TATLI KAŞIK.btw | L8: PLATİN | M8: DNC-092 PLATİN 6'LI TATLI KAŞIK | O8: 8683613550036 | P8: 8683613550036 | Q8: DÜZELTME GEREKLİ | R8: 8683613550036 barkodu şu ürün(ler)de de kullanılmış: DNC-181 (DNC_181 ORKİDE ÇAY KAŞIK 6,LI SADE). Bir barkod yalnızca tek bir ürüne ait olmalı. Bu ürünün kutusundaki/etiketindeki gerçek barkodu yazın; bu barkod başka ürüne aitse bu ürüne yeni barkod verin.
A9: DNC-003 | B9: Platin Tatlı Kaşığı (12'li) | C9: Kaşık | D9: Tatlı Kaşığı | E9: Platin | F9: Sade | G9: 12'li (1 DZ) | H9: 12 | J9: DNC-003 1 DZ PLATİN TATLI KAŞIK.btw | L9: PLATİN | M9: DNC-003 1 DZ PLATİN TATLI KAŞIK | O9: 8683581657034 | P9: 8683581657034 | Q9: TAMAM
A10: DNC-188 | B10: Platin Tatlı Kaşığı Titanium (6'lı) | C10: Kaşık | D10: Tatlı Kaşığı | E10: Platin | F10: Titanium | G10: 6'lı | H10: 6 | J10: DNC_188 PLATİN TATLI KAŞIK TİTANİUM 6,LI.btw | L10: PLATİN | M10: DNC_188 PLATİN TATLI KAŞIK TİTANİUM 6,LI | O10: 8683613550845 | P10: 8683613550845 | Q10: TAMAM
A11: DNC-100 | B11: Gümüş Tatlı Kaşığı (6'lı) | C11: Kaşık | D11: Tatlı Kaşığı | E11: Gümüş | F11: Sade | G11: 6'lı | H11: 6 | J11: DNC-100 6'LI GÜMÜŞ TATLI KAŞIK.btw | L11: GÜMÜŞ | M11: DNC-100 6'LI GÜMÜŞ TATLI KAŞIK | O11: 8683613550128 | P11: 8683613550128 | Q11: TAMAM
A12: DNC-052 | B12: Gümüş Tatlı Kaşığı (12'li) | C12: Kaşık | D12: Tatlı Kaşığı | E12: Gümüş | F12: Sade | G12: 12'li (1 DZ) | H12: 12 | J12: DNC-0052 1 DZ GÜMÜŞ TATLI KAŞIK.btw | L12: GÜMÜŞ | M12: DNC-0052 1 DZ GÜMÜŞ TATLI KAŞIK | N12: Kod yazımı hatalı: 'DNC-0052' → 'DNC-052' olmalı. | O12: 8683581657201 | P12: 8683581657201 | Q12: TAMAM
A13: DNC-107 | B13: Okyanus Tatlı Kaşığı (6'lı) | C13: Kaşık | D13: Tatlı Kaşığı | E13: Okyanus | F13: Sade | G13: 6'lı | H13: 6 | J13: DNC-107 6'LI OKYANUS TATLI KAŞIK.btw | L13: OKYANUS | M13: DNC-107 6'LI OKYANUS TATLI KAŞIK | O13: 8683613550197 | P13: 8683613550197 | Q13: TAMAM
A14: DNC-068 | B14: Okyanus Tatlı Kaşığı (12'li) | C14: Kaşık | D14: Tatlı Kaşığı | E14: Okyanus | F14: Sade | G14: 12'li (1 DZ) | H14: 12 | J14: DNC-068 1 DZ OKYANUS TATLI KAŞIK.btw | L14: OKYANUS | M14: DNC-068 1 DZ OKYANUS TATLI KAŞIK | O14: 8683581657324 | P14: 8683581657294 | Q14: DÜZELTME GEREKLİ | R14: • Bu listedeki barkod (8683581657324) ile barkod_listesi.xlsx'teki barkod (8683581657294) farklı. Hangisi doğru? • 8683581657294 barkodu şu ürün(ler)de de kullanılmış: DNC-066 (Okyanus Yemek Kaşığı (12'li)). Bir barkod yalnızca tek bir ürüne ait olmalı. Bu ürünün kutusundaki/etiketindeki gerçek barkodu yazın; bu barkod başka ürüne aitse bu ürüne yeni barkod verin. • 8683581657324 barkodu şu ürün(ler)de de kullanılmış: DNC-070 (Okyanus Çay Kaşığı (12'li)). Bir barkod yalnızca tek bir ürüne ait olmalı. Bu ürünün kutusundaki/etiketindeki gerçek barkodu yazın; bu barkod başka ürüne aitse bu ürüne yeni barkod verin.
A15: DNC-113 | B15: Gökkuşağı Tatlı Kaşığı (6'lı) | C15: Kaşık | D15: Tatlı Kaşığı | E15: Gökkuşağı | F15: Sade | G15: 6'lı | H15: 6 | J15: DNC-113 6'LI GÖKKUŞAK TATLI KAŞIK.btw | L15: GÖKKUŞAĞI | M15: DNC-113 6'LI GÖKKUŞAK TATLI KAŞIK | O15: 8683613550258 | P15: 8683613550258 | Q15: TAMAM
A16: DNC-080 | B16: Gökkuşağı Tatlı Kaşığı (12'li) | C16: Kaşık | D16: Tatlı Kaşığı | E16: Gökkuşağı | F16: Sade | G16: 12'li (1 DZ) | H16: 12 | J16: DNC-080 1 DZ GÖKKUŞAK TATLI KAŞIK.btw | L16: GÖKKUŞAĞI | M16: DNC-080 1 DZ GÖKKUŞAK TATLI KAŞIK | O16: 8683581657386 | P16: 8683581657386 | Q16: TAMAM
A17: DNC-089 | B17: Platin Yemek Kaşığı (6'lı) | C17: Kaşık | D17: Yemek Kaşığı | E17: Platin | F17: Sade | G17: 6'lı | H17: 6 | J17: DNC-089 PLATİN 6'LI YEMEK KAŞIK.btw | L17: PLATİN | M17: DNC-089 PLATİN 6'LI YEMEK KAŞIK | O17: 8683613550005 | P17: 8683613550005 | Q17: DÜZELTME GEREKLİ | R17: 8683613550005 barkodu şu ürün(ler)de de kullanılmış: DNC-207 (DNC_207 5,Lİ GOLD BLACK SERVİS SET). Bir barkod yalnızca tek bir ürüne ait olmalı. Bu ürünün kutusundaki/etiketindeki gerçek barkodu yazın; bu barkod başka ürüne aitse bu ürüne yeni barkod verin.
A18: DNC-001 | B18: Platin Yemek Kaşığı (12'li) | C18: Kaşık | D18: Yemek Kaşığı | E18: Platin | F18: Sade | G18: 12'li (1 DZ) | H18: 12 | J18: DNC-001 1 DZ PLATİN YEMEK KAŞIK.btw | L18: PLATİN | M18: DNC-001 1 DZ PLATİN YEMEK KAŞIK | O18: 8683581657003 | P18: 8683581657003 | Q18: DÜZELTME GEREKLİ | R18: 8683581657003 barkodu şu ürün(ler)de de kullanılmış: DNC-077 (Okyanus 72 Parça Çatal-Kaşık-Bıçak Seti). Bir barkod yalnızca tek bir ürüne ait olmalı. Bu ürünün kutusundaki/etiketindeki gerçek barkodu yazın; bu barkod başka ürüne aitse bu ürüne yeni barkod verin.
A19: DNC-186 | B19: Platin Yemek Kaşığı Titanium (6'lı) | C19: Kaşık | D19: Yemek Kaşığı | E19: Platin | F19: Titanium | G19: 6'lı | H19: 6 | J19: DNC_186 PLATİN YEMEK KAŞIK TİTANİUM 6,LI.btw | L19: PLATİN | M19: DNC_186 PLATİN YEMEK KAŞIK TİTANİUM 6,LI | O19: 8683613550821 | P19: 8683613550821 | Q19: TAMAM
A20: DNC-098 | B20: Gümüş Yemek Kaşığı (6'lı) | C20: Kaşık | D20: Yemek Kaşığı | E20: Gümüş | F20: Sade | G20: 6'lı | H20: 6 | J20: DNC-098 6'LI GÜMÜŞ YEMEK KAŞIK.btw | L20: GÜMÜŞ | M20: DNC-098 6'LI GÜMÜŞ YEMEK KAŞIK | O20: 8683613550098 | P20: 8683613550098 | Q20: TAMAM
A21: DNC-050 | B21: Gümüş Yemek Kaşığı (12'li) | C21: Kaşık | D21: Yemek Kaşığı | E21: Gümüş | F21: Sade | G21: 12'li (1 DZ) | H21: 12 | J21: DNC-050 1 DZ GÜMÜŞ YEMEK KAŞIK.btw | L21: GÜMÜŞ | M21: DNC-050 1 DZ GÜMÜŞ YEMEK KAŞIK | O21: 8683581657171 | P21: 8683581657171 | Q21: TAMAM
A22: DNC-105 | B22: Okyanus Yemek Kaşığı (6'lı) | C22: Kaşık | D22: Yemek Kaşığı | E22: Okyanus | F22: Sade | G22: 6'lı | H22: 6 | J22: DNC-105 6'LI OKYANUS YEMEK KAŞIK.btw | L22: OKYANUS | M22: DNC-105 6'LI OKYANUS YEMEK KAŞIK | O22: 8683613550166 | P22: 8683613550166 | Q22: TAMAM
A23: DNC-066 | B23: Okyanus Yemek Kaşığı (12'li) | C23: Kaşık | D23: Yemek Kaşığı | E23: Okyanus | F23: Sade | G23: 12'li (1 DZ) | H23: 12 | J23: DNC-066 1 DZ OKYANUS YEMEK KAŞIK.btw | L23: OKYANUS | M23: DNC-066 1 DZ OKYANUS YEMEK KAŞIK | O23: 8683581657294 | Q23: DÜZELTME GEREKLİ | R23: • 8683581657294 barkodu şu ürün(ler)de de kullanılmış: DNC-068 (Okyanus Tatlı Kaşığı (12'li)). Bir barkod yalnızca tek bir ürüne ait olmalı. Bu ürünün kutusundaki/etiketindeki gerçek barkodu yazın; bu barkod başka ürüne aitse bu ürüne yeni barkod verin. • Bilgi: Bu ürün sonradan gönderdiğiniz barkod_listesi.xlsx'te yok. Ürün hâlâ üretiliyor mu?
A24: DNC-111 | B24: Gökkuşağı Yemek Kaşığı (6'lı) | C24: Kaşık | D24: Yemek Kaşığı | E24: Gökkuşağı | F24: Sade | G24: 6'lı | H24: 6 | J24: DNC-111 6'LI GÖKKUŞAK YEMEK KAŞIK.btw | L24: GÖKKUŞAĞI | M24: DNC-111 6'LI GÖKKUŞAK YEMEK KAŞIK | O24: 8683613550227 | P24: 8683613550227 | Q24: TAMAM
A25: DNC-078 | B25: Gökkuşağı Yemek Kaşığı (12'li) | C25: Kaşık | D25: Yemek Kaşığı | E25: Gökkuşağı | F25: Sade | G25: 12'li (1 DZ) | H25: 12 | J25: DNC-078 1 DZ GÖKKUŞAK YEMEK KAŞIK.btw | L25: GÖKKUŞAĞI | M25: DNC-078 1 DZ GÖKKUŞAK YEMEK KAŞIK | O25: 8683581657362 | P25: 8683581657362 | Q25: TAMAM
A26: DNC-125 | B26: Platin Çay Kaşığı Gold (12'li) | C26: Kaşık | D26: Çay Kaşığı | E26: Platin | F26: Gold | G26: 12'li (1 DZ) | H26: 12 | J26: DNC-125 1DZ PLATİN GOLD ÇAY KAŞIK.btw | L26: PLATİN | M26: DNC-125 1DZ PLATİN GOLD ÇAY KAŞIK | N26: Platin serisinde tek Gold ürün. | O26: 8683613550357 | P26: 8683613550357 | Q26: TAMAM
A27: DNC-093 | B27: Platin Çay Kaşığı (6'lı) | C27: Kaşık | D27: Çay Kaşığı | E27: Platin | F27: Sade | G27: 6'lı | H27: 6 | J27: DNC-093 PLATİN 6,LI ÇAY KAŞIK.btw | L27: PLATİN | M27: DNC-093 PLATİN 6,LI ÇAY KAŞIK | O27: 8683613550067 | P27: 8683613550067 | Q27: TAMAM
A28: DNC-005 | B28: Platin Çay Kaşığı (12'li) | C28: Kaşık | D28: Çay Kaşığı | E28: Platin | F28: Sade | G28: 12'li (1 DZ) | H28: 12 | J28: DNC-005 1 DZ PLATİN ÇAY KAŞIK.btw | L28: PLATİN | M28: DNC-005 1 DZ PLATİN ÇAY KAŞIK | O28: 8683581657058 | P28: 8683581657058 | Q28: TAMAM
A29: DNC-190 | B29: Platin Çay Kaşığı Titanium (6'lı) | C29: Kaşık | D29: Çay Kaşığı | E29: Platin | F29: Titanium | G29: 6'lı | H29: 6 | J29: DNC_190 PLATİN ÇAY KAŞIK TİTANİUM 6,LI.btw | L29: PLATİN | M29: DNC_190 PLATİN ÇAY KAŞIK TİTANİUM 6,LI | O29: 8683613550869 | P29: 8683613550869 | Q29: TAMAM
A30: DNC-102 | B30: Gümüş Çay Kaşığı (6'lı) | C30: Kaşık | D30: Çay Kaşığı | E30: Gümüş | F30: Sade | G30: 6'lı | H30: 6 | J30: DNC-102 6'LI GÜMÜŞ ÇAY KAŞIK.btw | L30: GÜMÜŞ | M30: DNC-102 6'LI GÜMÜŞ ÇAY KAŞIK | O30: 8683613550159 | P30: 8683613550159 | Q30: TAMAM
A31: DNC-054 | B31: Gümüş Çay Kaşığı (12'li) | C31: Kaşık | D31: Çay Kaşığı | E31: Gümüş | F31: Sade | G31: 12'li (1 DZ) | H31: 12 | J31: DNC-054 1 DZ GÜMÜŞ ÇAY KAŞIK.btw | L31: GÜMÜŞ | M31: DNC-054 1 DZ GÜMÜŞ ÇAY KAŞIK | O31: 8683581657225 | P31: 8683581657225 | Q31: TAMAM
A32: DNC-109 | B32: Okyanus Çay Kaşığı (6'lı) | C32: Kaşık | D32: Çay Kaşığı | E32: Okyanus | F32: Sade | G32: 6'lı | H32: 6 | J32: DNC-109 6'LI OKYANUS ÇAY KAŞIK.btw | L32: OKYANUS | M32: DNC-109 6'LI OKYANUS ÇAY KAŞIK | O32: 8683613550210 | P32: 8683613550210 | Q32: TAMAM
A33: DNC-070 | B33: Okyanus Çay Kaşığı (12'li) | C33: Kaşık | D33: Çay Kaşığı | E33: Okyanus | F33: Sade | G33: 12'li (1 DZ) | H33: 12 | J33: DNC-070 1 DZ OKYANUS ÇAY KAŞIK.btw | L33: OKYANUS | M33: DNC-070 1 DZ OKYANUS ÇAY KAŞIK | O33: 8683581657348 | P33: 8683581657324 | Q33: DÜZELTME GEREKLİ | R33: • Bu listedeki barkod (8683581657348) ile barkod_listesi.xlsx'teki barkod (8683581657324) farklı. Hangisi doğru? • 8683581657324 barkodu şu ürün(ler)de de kullanılmış: DNC-068 (Okyanus Tatlı Kaşığı (12'li)). Bir barkod yalnızca tek bir ürüne ait olmalı. Bu ürünün kutusundaki/etiketindeki gerçek barkodu yazın; bu barkod başka ürüne aitse bu ürüne yeni barkod verin. • 8683581657348 barkodu şu ürün(ler)de de kullanılmış: DNC-072 (OKYANUS 30 PRÇ ÇKB SET). Bir barkod yalnızca tek bir ürüne ait olmalı. Bu ürünün kutusundaki/etiketindeki gerçek barkodu yazın; bu barkod başka ürüne aitse bu ürüne yeni barkod verin.
A34: DNC-115 | B34: Gökkuşağı Çay Kaşığı (6'lı) | C34: Kaşık | D34: Çay Kaşığı | E34: Gökkuşağı | F34: Sade | G34: 6'lı | H34: 6 | J34: DNC-115 6'LI GÖKKUŞAK ÇAY KAŞIK.btw | L34: GÖKKUŞAĞI | M34: DNC-115 6'LI GÖKKUŞAK ÇAY KAŞIK | O34: 8683613550272 | P34: 8683613550272 | Q34: TAMAM
A35: DNC-082 | B35: Gökkuşağı Çay Kaşığı (12'li) | C35: Kaşık | D35: Çay Kaşığı | E35: Gökkuşağı | F35: Sade | G35: 12'li (1 DZ) | H35: 12 | J35: DNC-082 1 DZ GÖKKUŞAK ÇAY KAŞIK.btw | L35: GÖKKUŞAĞI | M35: DNC-082 1 DZ GÖKKUŞAK ÇAY KAŞIK | O35: 8683581657409 | P35: 8683581657409 | Q35: TAMAM
A36: DNC-091 | B36: Platin Tatlı Çatalı (6'lı) | C36: Çatal | D36: Tatlı Çatalı | E36: Platin | F36: Sade | G36: 6'lı | H36: 6 | J36: DNC-091 PLATİN 6'LI TATLI ÇATAL.btw | L36: PLATİN | M36: DNC-091 PLATİN 6'LI TATLI ÇATAL | O36: 8683613550043 | P36: 8683613550043 | Q36: TAMAM
A37: DNC-004 | B37: Platin Tatlı Çatalı (12'li) | C37: Çatal | D37: Tatlı Çatalı | E37: Platin | F37: Sade | G37: 12'li (1 DZ) | H37: 12 | J37: DNC-004 1 DZ PLATİN TATLI ÇATAL.btw | L37: PLATİN | M37: DNC-004 1 DZ PLATİN TATLI ÇATAL | O37: 8683581657041 | P37: 8683581657041 | Q37: TAMAM
A38: DNC-189 | B38: Platin Tatlı Çatalı Titanium (6'lı) | C38: Çatal | D38: Tatlı Çatalı | E38: Platin | F38: Titanium | G38: 6'lı | H38: 6 | J38: DNC_189 PLATİN TATLI ÇATAL TİTANİUM 6,LI.btw | L38: PLATİN | M38: DNC_189 PLATİN TATLI ÇATAL TİTANİUM 6,LI | O38: 8683613550852 | P38: 8683613550852 | Q38: TAMAM
A39: DNC-101 | B39: Gümüş Tatlı Çatalı (6'lı) | C39: Çatal | D39: Tatlı Çatalı | E39: Gümüş | F39: Sade | G39: 6'lı | H39: 6 | J39: DNC-101 6'LI GÜMÜŞ TATLI ÇATAL.btw | L39: GÜMÜŞ | M39: DNC-101 6'LI GÜMÜŞ TATLI ÇATAL | O39: 8683613550135 | P39: 8683613550135 | Q39: TAMAM
A40: DNC-053 | B40: Gümüş Tatlı Çatalı (12'li) | C40: Çatal | D40: Tatlı Çatalı | E40: Gümüş | F40: Sade | G40: 12'li (1 DZ) | H40: 12 | J40: DNC-053 1 DZ GÜMÜŞ TATLI ÇATAL.btw | L40: GÜMÜŞ | M40: DNC-053 1 DZ GÜMÜŞ TATLI ÇATAL | O40: 8683581657218 | P40: 8683581657218 | Q40: TAMAM
...

Sheet Özet
A1: Ana Kategori × Model (adet = ürün/SKU sayısı)
A3: Ana Kategori | B3: Platin | C3: Gümüş | D3: Okyanus | E3: Gökkuşağı | F3: Damla | G3: Kelebek | H3: Zerafet | I3: TOPLAM
A4: Kaşık | B4: =COUNTIFS('Ürün Listesi'!$C$2:$C$139,$A4,'Ürün Listesi'!$E$2:$E$139,B$3) | C4: =COUNTIFS('Ürün Listesi'!$C$2:$C$139,$A4,'Ürün Listesi'!$E$2:$E$139,C$3) | D4: =COUNTIFS('Ürün Listesi'!$C$2:$C$139,$A4,'Ürün Listesi'!$E$2:$E$139,D$3) | E4: =COUNTIFS('Ürün Listesi'!$C$2:$C$139,$A4,'Ürün Listesi'!$E$2:$E$139,E$3) | F4: =COUNTIFS('Ürün Listesi'!$C$2:$C$139,$A4,'Ürün Listesi'!$E$2:$E$139,F$3) | G4: =COUNTIFS('Ürün Listesi'!$C$2:$C$139,$A4,'Ürün Listesi'!$E$2:$E$139,G$3) | H4: =COUNTIFS('Ürün Listesi'!$C$2:$C$139,$A4,'Ürün Listesi'!$E$2:$E$139,H$3) | I4: =SUM(B4:H4)
A5: Çatal | B5: =COUNTIFS('Ürün Listesi'!$C$2:$C$139,$A5,'Ürün Listesi'!$E$2:$E$139,B$3) | C5: =COUNTIFS('Ürün Listesi'!$C$2:$C$139,$A5,'Ürün Listesi'!$E$2:$E$139,C$3) | D5: =COUNTIFS('Ürün Listesi'!$C$2:$C$139,$A5,'Ürün Listesi'!$E$2:$E$139,D$3) | E5: =COUNTIFS('Ürün Listesi'!$C$2:$C$139,$A5,'Ürün Listesi'!$E$2:$E$139,E$3) | F5: =COUNTIFS('Ürün Listesi'!$C$2:$C$139,$A5,'Ürün Listesi'!$E$2:$E$139,F$3) | G5: =COUNTIFS('Ürün Listesi'!$C$2:$C$139,$A5,'Ürün Listesi'!$E$2:$E$139,G$3) | H5: =COUNTIFS('Ürün Listesi'!$C$2:$C$139,$A5,'Ürün Listesi'!$E$2:$E$139,H$3) | I5: =SUM(B5:H5)
A6: Bıçak | B6: =COUNTIFS('Ürün Listesi'!$C$2:$C$139,$A6,'Ürün Listesi'!$E$2:$E$139,B$3) | C6: =COUNTIFS('Ürün Listesi'!$C$2:$C$139,$A6,'Ürün Listesi'!$E$2:$E$139,C$3) | D6: =COUNTIFS('Ürün Listesi'!$C$2:$C$139,$A6,'Ürün Listesi'!$E$2:$E$139,D$3) | E6: =COUNTIFS('Ürün Listesi'!$C$2:$C$139,$A6,'Ürün Listesi'!$E$2:$E$139,E$3) | F6: =COUNTIFS('Ürün Listesi'!$C$2:$C$139,$A6,'Ürün Listesi'!$E$2:$E$139,F$3) | G6: =COUNTIFS('Ürün Listesi'!$C$2:$C$139,$A6,'Ürün Listesi'!$E$2:$E$139,G$3) | H6: =COUNTIFS('Ürün Listesi'!$C$2:$C$139,$A6,'Ürün Listesi'!$E$2:$E$139,H$3) | I6: =SUM(B6:H6)
A7: Çatal-Kaşık-Bıçak Seti | B7: =COUNTIFS('Ürün Listesi'!$C$2:$C$139,$A7,'Ürün Listesi'!$E$2:$E$139,B$3) | C7: =COUNTIFS('Ürün Listesi'!$C$2:$C$139,$A7,'Ürün Listesi'!$E$2:$E$139,C$3) | D7: =COUNTIFS('Ürün Listesi'!$C$2:$C$139,$A7,'Ürün Listesi'!$E$2:$E$139,D$3) | E7: =COUNTIFS('Ürün Listesi'!$C$2:$C$139,$A7,'Ürün Listesi'!$E$2:$E$139,E$3) | F7: =COUNTIFS('Ürün Listesi'!$C$2:$C$139,$A7,'Ürün Listesi'!$E$2:$E$139,F$3) | G7: =COUNTIFS('Ürün Listesi'!$C$2:$C$139,$A7,'Ürün Listesi'!$E$2:$E$139,G$3) | H7: =COUNTIFS('Ürün Listesi'!$C$2:$C$139,$A7,'Ürün Listesi'!$E$2:$E$139,H$3) | I7: =SUM(B7:H7)
A8: Servis Ürünleri | B8: =COUNTIFS('Ürün Listesi'!$C$2:$C$139,$A8,'Ürün Listesi'!$E$2:$E$139,B$3) | C8: =COUNTIFS('Ürün Listesi'!$C$2:$C$139,$A8,'Ürün Listesi'!$E$2:$E$139,C$3) | D8: =COUNTIFS('Ürün Listesi'!$C$2:$C$139,$A8,'Ürün Listesi'!$E$2:$E$139,D$3) | E8: =COUNTIFS('Ürün Listesi'!$C$2:$C$139,$A8,'Ürün Listesi'!$E$2:$E$139,E$3) | F8: =COUNTIFS('Ürün Listesi'!$C$2:$C$139,$A8,'Ürün Listesi'!$E$2:$E$139,F$3) | G8: =COUNTIFS('Ürün Listesi'!$C$2:$C$139,$A8,'Ürün Listesi'!$E$2:$E$139,G$3) | H8: =COUNTIFS('Ürün Listesi'!$C$2:$C$139,$A8,'Ürün Listesi'!$E$2:$E$139,H$3) | I8: =SUM(B8:H8)
A9: Sos Servis Ürünleri | B9: =COUNTIFS('Ürün Listesi'!$C$2:$C$139,$A9,'Ürün Listesi'!$E$2:$E$139,B$3) | C9: =COUNTIFS('Ürün Listesi'!$C$2:$C$139,$A9,'Ürün Listesi'!$E$2:$E$139,C$3) | D9: =COUNTIFS('Ürün Listesi'!$C$2:$C$139,$A9,'Ürün Listesi'!$E$2:$E$139,D$3) | E9: =COUNTIFS('Ürün Listesi'!$C$2:$C$139,$A9,'Ürün Listesi'!$E$2:$E$139,E$3) | F9: =COUNTIFS('Ürün Listesi'!$C$2:$C$139,$A9,'Ürün Listesi'!$E$2:$E$139,F$3) | G9: =COUNTIFS('Ürün Listesi'!$C$2:$C$139,$A9,'Ürün Listesi'!$E$2:$E$139,G$3) | H9: =COUNTIFS('Ürün Listesi'!$C$2:$C$139,$A9,'Ürün Listesi'!$E$2:$E$139,H$3) | I9: =SUM(B9:H9)
A10: Maşa | B10: =COUNTIFS('Ürün Listesi'!$C$2:$C$139,$A10,'Ürün Listesi'!$E$2:$E$139,B$3) | C10: =COUNTIFS('Ürün Listesi'!$C$2:$C$139,$A10,'Ürün Listesi'!$E$2:$E$139,C$3) | D10: =COUNTIFS('Ürün Listesi'!$C$2:$C$139,$A10,'Ürün Listesi'!$E$2:$E$139,D$3) | E10: =COUNTIFS('Ürün Listesi'!$C$2:$C$139,$A10,'Ürün Listesi'!$E$2:$E$139,E$3) | F10: =COUNTIFS('Ürün Listesi'!$C$2:$C$139,$A10,'Ürün Listesi'!$E$2:$E$139,F$3) | G10: =COUNTIFS('Ürün Listesi'!$C$2:$C$139,$A10,'Ürün Listesi'!$E$2:$E$139,G$3) | H10: =COUNTIFS('Ürün Listesi'!$C$2:$C$139,$A10,'Ürün Listesi'!$E$2:$E$139,H$3) | I10: =SUM(B10:H10)
A11: Sunum / Sosluk | B11: =COUNTIFS('Ürün Listesi'!$C$2:$C$139,$A11,'Ürün Listesi'!$E$2:$E$139,B$3) | C11: =COUNTIFS('Ürün Listesi'!$C$2:$C$139,$A11,'Ürün Listesi'!$E$2:$E$139,C$3) | D11: =COUNTIFS('Ürün Listesi'!$C$2:$C$139,$A11,'Ürün Listesi'!$E$2:$E$139,D$3) | E11: =COUNTIFS('Ürün Listesi'!$C$2:$C$139,$A11,'Ürün Listesi'!$E$2:$E$139,E$3) | F11: =COUNTIFS('Ürün Listesi'!$C$2:$C$139,$A11,'Ürün Listesi'!$E$2:$E$139,F$3) | G11: =COUNTIFS('Ürün Listesi'!$C$2:$C$139,$A11,'Ürün Listesi'!$E$2:$E$139,G$3) | H11: =COUNTIFS('Ürün Listesi'!$C$2:$C$139,$A11,'Ürün Listesi'!$E$2:$E$139,H$3) | I11: =SUM(B11:H11)
A12: Belirsiz | B12: =COUNTIFS('Ürün Listesi'!$C$2:$C$139,$A12,'Ürün Listesi'!$E$2:$E$139,B$3) | C12: =COUNTIFS('Ürün Listesi'!$C$2:$C$139,$A12,'Ürün Listesi'!$E$2:$E$139,C$3) | D12: =COUNTIFS('Ürün Listesi'!$C$2:$C$139,$A12,'Ürün Listesi'!$E$2:$E$139,D$3) | E12: =COUNTIFS('Ürün Listesi'!$C$2:$C$139,$A12,'Ürün Listesi'!$E$2:$E$139,E$3) | F12: =COUNTIFS('Ürün Listesi'!$C$2:$C$139,$A12,'Ürün Listesi'!$E$2:$E$139,F$3) | G12: =COUNTIFS('Ürün Listesi'!$C$2:$C$139,$A12,'Ürün Listesi'!$E$2:$E$139,G$3) | H12: =COUNTIFS('Ürün Listesi'!$C$2:$C$139,$A12,'Ürün Listesi'!$E$2:$E$139,H$3) | I12: =SUM(B12:H12)
A13: TOPLAM | B13: =SUM(B4:B12) | C13: =SUM(C4:C12) | D13: =SUM(D4:D12) | E13: =SUM(E4:E12) | F13: =SUM(F4:F12) | G13: =SUM(G4:G12) | H13: =SUM(H4:H12) | I13: =SUM(I4:I12)
A15: Barkod dosyası olan ürün | B15: =COUNTIF('Ürün Listesi'!$J$2:$J$139,"*.btw")
A16: Barkodsuz (sadece foto) | B16: =COUNTIF('Ürün Listesi'!$J$2:$J$139,"— yok —")
A17: Kontrol notu olan satır | B17: =COUNTIF('Ürün Listesi'!$N$2:$N$139,"?*")
A19: Kaplama dağılımı
A20: Sade | B20: =COUNTIF('Ürün Listesi'!$F$2:$F$139,A20)
A21: Titanium | B21: =COUNTIF('Ürün Listesi'!$F$2:$F$139,A21)
A22: Mat Titanium | B22: =COUNTIF('Ürün Listesi'!$F$2:$F$139,A22)
A23: Gold | B23: =COUNTIF('Ürün Listesi'!$F$2:$F$139,A23)
A24: Mira Gold | B24: =COUNTIF('Ürün Listesi'!$F$2:$F$139,A24)
A25: Antik Gold | B25: =COUNTIF('Ürün Listesi'!$F$2:$F$139,A25)
A26: Gümüş | B26: =COUNTIF('Ürün Listesi'!$F$2:$F$139,A26)

Sheet Kontrol Edilecekler
A1: Konu | B1: Detay
A2: Kodsuz barkodlar | B2: GÜMÜŞ klasöründe "GÜMÜŞ 84 PRÇ ÇKB SET" ve "GÜMÜŞ 89 PRÇ ÇKB SET" dosyalarında DNC kodu yok.
A3: Barkodu olmayan kodlu ürünler | B3: DNC-021, DNC-022 (Platin Mira Gold?), DNC-151, DNC-152 (Kelebek sosluk), DNC-175, 176, 177, 179 (Mira Gold sos servis) — sadece foto var, .btw yok.
A4: Yazım hataları | B4: DNC-0052 (→ DNC-052), "DNC-037 SALATA MAŞASI [430)", "DNC-163OKYANUS" (boşluk yok). Kodlarda DNC- ve DNC_ karışık kullanılmış.
A5: Yanlış klasör | B5: DNC-120 ve DNC-123 Kelebek maşa setleri "DAMLA MODEL MAŞA FOTOĞRAFLARI" klasöründe.
A6: Kaplama çelişkisi | B6: DNC-155: barkodda Titanium, fotoda Gold. DNC-172: barkodda Mat Titanium, fotoda Mat Gold.
A7: Mira Gold | B7: DNC-021/022 Platin klasöründe, DNC-173/175-179 Okyanus klasöründe "Mira Gold" geçiyor. Ayrı bir model mi, kaplama adı mı netleştir.
A8: Kod sıralamasındaki boşluklar | B8: 016, 023, 024, 026, 027, 028, 031, 032, 033, 034, 035, 039, 041, 042, 043, 044, 045, 046, 047, 048, 072, 075, 076, 117, 118, 119, 121, 124, 126, 127, 128, 129, 130, 131, 132, 133, 134, 135, 136, 138, 141, 142, 143, 144, 145, 146, 148, 150, 153, 154, 156, 174, 178, 180, 181, 182, 183, 184, 185, 193, 194, 195, 196, 197, 198, 199, 200, 201, 202, 203, 204, 207, 208 — bu numaralarda hiçbir dosya yok (üretilmeyen, eski ya da barkodu kayıp ürünler olabilir; ör. DNC-178 büyük ihtimalle Mira Gold sos spatula).
A9: Barkod numaraları | B9: .btw (BarTender) dosyaları sıkıştırılmış formatta, içindeki EAN numarası dışarıdan okunamadı. Numaraları eklemek için BarTender'dan dışa aktarım (CSV) gerekiyor.

Sheet Fotoğraflar
A1: Klasör | B1: Dosya | C1: Dosya Adındaki Kod | D1: Eşleşecek Ürün Kodu (sen doldur)
A2: DAMLA MODEL MAŞA FOTOĞRAFLARI | B2: 3,LÜ_MAŞA_SET_SADE.JPG
A3: DAMLA MODEL MAŞA FOTOĞRAFLARI | B3: DAMLA MODEL GOLD MAŞA SET (altın).JPG
A4: DAMLA MODEL MAŞA FOTOĞRAFLARI | B4: DAMLA MODEL SADE MAŞA.jpg
A5: DAMLA MODEL MAŞA FOTOĞRAFLARI | B5: DNC-040 3'LÜ MAŞA SET TİTANİUM.jpeg | C5: DNC-040 | D5: DNC-040
A6: DAMLA MODEL MAŞA FOTOĞRAFLARI | B6: DNC_120 GOLD KELEBEK MAŞA SET.jpeg | C6: DNC-120 | D6: DNC-120
A7: DAMLA MODEL MAŞA FOTOĞRAFLARI | B7: DNC_139 DAMLA SADE MAŞA SET.jpeg | C7: DNC-139 | D7: DNC-139
A8: DAMLA MODEL MAŞA FOTOĞRAFLARI | B8: DSC_1744.JPG
A9: DAMLA MODEL MAŞA FOTOĞRAFLARI | B9: DSC_1745.JPG
A10: DAMLA MODEL MAŞA FOTOĞRAFLARI | B10: DSC_1746.JPG
A11: DAMLA MODEL MAŞA FOTOĞRAFLARI | B11: DSC_1747.JPG
A12: DAMLA MODEL MAŞA FOTOĞRAFLARI | B12: DSC_1790.JPG
A13: DAMLA MODEL MAŞA FOTOĞRAFLARI | B13: DSC_1791.JPG
A14: DAMLA MODEL MAŞA FOTOĞRAFLARI | B14: MAŞASETSADE (2).jpeg
A15: DAMLA MODEL MAŞA FOTOĞRAFLARI | B15: MAŞASETSADE.jpeg
A16: GÖKKUŞAĞI/GÖKKUŞAK MODEL FOTOĞRAF | B16: GÖKKUŞAK.jpeg
A17: GÖKKUŞAĞI/GÖKKUŞAK MODEL FOTOĞRAF | B17: GÖKKUŞAKMODEL.jpeg
A18: GÖKKUŞAĞI/GÖKKUŞAK MODEL FOTOĞRAF | B18: GÖKKUŞAĞI.mp4
A19: GÜMÜŞ/GÜMÜŞ MODEL FOTOGRAFLAR | B19: GMŞ_SERVİS_SET.JPG
... A25: GÜMÜŞ/GÜMÜŞ MODEL FOTOGRAFLAR | B25: WhatsApp Image 2026-08-12 at 09.21.43.jpeg
A26: KELEBEK SUNUM SOSLUK FOTOGRAFI | B26: DNC_151 GOLD KELEBEK SUNUM SOSLUK.jpeg | C26: DNC-151 | D26: DNC-151
A27: KELEBEK SUNUM SOSLUK FOTOGRAFI | B27: DNC_152 GÜMÜŞ KELEBEK SUNUM SOSLUK.jpeg | C27: DNC-152 | D27: DNC-152
A28: KELEBEK SUNUM SOSLUK FOTOGRAFI | B28: WhatsApp Image 2026-08-27 at 10.19.54 (1).jpeg
A29: KELEBEK SUNUM SOSLUK FOTOGRAFI | B29: WhatsApp Image 2026-08-27 at 10.19.54 (2).jpeg
A30: KELEBEK SUNUM SOSLUK FOTOGRAFI | B30: WhatsApp Image 2026-08-27 at 10.19.54 (3).jpeg
A31: KELEBEK SUNUM SOSLUK FOTOGRAFI | B31: WhatsApp Image 2026-08-27 at 10.19.54.jpeg
A32: OKYANUS | B32: DNC_173 5,Lİ SOS SERVİS SET MİRA GOLD.jpeg | C32: DNC-173 | D32: DNC-173
A33: OKYANUS | B33: DNC_175 MİRA GOLD SOS SERVİS KEPÇE.jpeg | C33: DNC-175 | D33: DNC-175
A34: OKYANUS | B34: DNC_176 MİRA GOLD SOS SERVİS KEVGİR.jpeg | C34: DNC-176 | D34: DNC-176
A35: OKYANUS | B35: DNC_177 MİRA GOLD SOS SERVİS KAŞIK.jpeg | C35: DNC-177 | D35: DNC-177
A36: OKYANUS | B36: DNC_179 MİRA GOLD SOS SERVİS ÇATAL.jpeg | C36: DNC-179 | D36: DNC-179
A37: OKYANUS/OKYANUS MODEL FOTOGRAFLAR | B37: DNC172.jpg | C37: DNC-172 | D37: DNC-172
A38: OKYANUS/OKYANUS MODEL FOTOGRAFLAR | B38: DNC_172 SOS SERVİS SETMAT GOLD.jpg | C38: DNC-172 | D38: DNC-172
A39: OKYANUS/OKYANUS MODEL FOTOGRAFLAR | B39: IMG_7958.jpg
A40: OKYANUS/OKYANUS MODEL FOTOGRAFLAR | B40: IMG_8006.jpg
A41: OKYANUS/OKYANUS MODEL FOTOGRAFLAR | B41: OKYANUS.jpeg
A42: OKYANUS/OKYANUS MODEL FOTOGRAFLAR | B42: OKYANUSMODEL Ç.K.B SET.jpg
A43: OKYANUS/OKYANUS MODEL FOTOGRAFLAR | B43: SOS_SERVİS_ALTIN_KAPLAMA.jpg
A44: OKYANUS/OKYANUS MODEL FOTOGRAFLAR | B44: SOS_SERVİS_SETİ_ALTIN_KAPLAMA_2.jpg
A45: OKYANUS/OKYANUS MODEL FOTOGRAFLAR | B45: SOS_SERVİS_SETİ_TİTANİUM.jpg
...
